Workbook

Sheet AUGUST
A1: =SUBTOTAL(2,#REF!) -> #REF! | AL1: =SUBTOTAL(9,#REF!) -> #REF! | AM1: =SUBTOTAL(9,#REF!) -> #REF! | AN1: =SUBTOTAL(9,#REF!) -> #REF! | AO1: =SUBTOTAL(9,#REF!) -> #REF! | AP1: =SUBTOTAL(9,#REF!) -> #REF! | AQ1: =SUBTOTAL(9,#REF!) -> #REF! | AR1: =SUBTOTAL(9,#REF!) -> #REF! | AS1: =SUBTOTAL(9,#REF!) -> #REF! | ... AU1: =SUBTOTAL(9,#REF!) -> #REF!
A2: STT | B2: Month | C2: Week | D2: Transferred Date | E2: Complete Date | F2: SỐ NGÀY GIAO | G2: SATUS | H2: Return Date | I2: Order Type | J2: Ma Don Tiki | K2: Ma Don GHN | L2: ID | M2: Status | N2: COD | O2: Ngày chuyển COD | P2: SLA Leadtime | Q2: From Address | R2: From 0 | S2: From 1 | T2: From 2 | U2: From 3 | V2: From 4 | W2: From Area | X2: To Address | Y2: To 0 | Z2: To 1 | AA2: To 2 | AB2: To 3 | AC2: To 4 | AD2: To Area | AE2: Route | AF2: Route Tier | AG2: Weight (kg) | AH2: Length (cm) | AI2: Height (cm) | AJ2: Width (cm) | AK2: Conversion Weight | AL2: Charge Weight | AM2: Apply Fee | AN2: Transport Fee | AO2: Return Fee | AP2: Linehaul Fee | AQ2: Total Fee | AR2: Discount | AS2: Total Fee After Discount | AT2: VAT | AU2: Total Fee With VAT | AV2: Tiki Note (Kg) | AW2: GHN Note (Kg) | AX2: Charge Weight | AY2: Transport Fee | AZ2: GAP | BA2: type (check) | BB2: Type (Final)
A3: SAMPLE | F3: =INT(DATE(YEAR(E3),MONTH(E3),DAY(E3))-DATE(YEAR(D3),MONTH(D3),DAY(D3))) -> 0 | G3: =IF(AND((LEFT(M3,4)="Giao"),F3<=VALUE(LEFT(P3,1))), "On time",IF(OR(LEFT(M3,3)="Trả",LEFT(M3,3)="Mất")," "," Late")) | I3: =IF(MID(K3,6,7)="AMSPICK","C-Return",IF(OR(LEFT(K3,5)="GHNTK",LEFT(K3,5)="GTKMP"),"Delivery","System Booking")) -> System Booking | J3: 386924126 | K3: 31429951259867 | L3: 1367 | M3: Trả thành công/Hoàn tất | N3: 713400 | O3: 44180.415 | P3: 2 Ngày | Q3: 1058 - Bưu Cục 254-256 Âu Cơ-Q.Liên Chiểu-Đà Nẵng | R3: =IF(FIND("-",Q3,1)-1=5,VLOOKUP(REPLACE(Q3,1,7,""),'Bảng giá '!$Y:$AB,2,0),VLOOKUP(REPLACE(Q3,1,11,""),'Bảng giá '!$Y:$AB,2,0)) -> Quận Liên Chiểu - Đà Nẵng | S3: =VLOOKUP(R3,'Bảng giá '!$K:$Q,3,0) -> Đà Nẵng | T3: =VLOOKUP(R3,'Bảng giá '!$K:$Q,2,0) -> Quận Liên Chiểu | U3: =VLOOKUP(R3,'Bảng giá '!$K$1:$Q$768,6,0) -> North central | V3: =VLOOKUP(R3,'Bảng giá '!$K:$N,4,0) -> urban | W3: =VLOOKUP(R3,'Bảng giá '!$K:$Q,7,0) -> Đà Nẵng | X3: a51 khu dan cu Tan thuan nam,, Phường Phú Thuận, Quận 7, Hồ Chí Minh | Y3: Quận Hải Châu - Đà Nẵng | Z3: =VLOOKUP(Y3,'Bảng giá '!$K$1:$M$768,3,0) -> Đà Nẵng | AA3: =VLOOKUP(Y3,'Bảng giá '!$K:$Q,2,0) -> Quận Hải Châu | AB3: =VLOOKUP(Y3,'Bảng giá '!$K$1:$Q$768,6,0) -> North central | AC3: =VLOOKUP(Y3,'Bảng giá '!K:N,4,0) -> urban | AD3: =VLOOKUP(Y3,'Bảng giá '!K:Q,7,0) -> Đà Nẵng | AE3: =IF(AND(S3=Y3,W3<>"HCM",W3<>"Hà Nội",W3<>"Đà Nẵng"),"Same Province",INDEX('Bảng giá '!$B$22:$G$28,MATCH(W3,'Bảng giá '!$A$22:$A$28,0),MATCH(AD3,'Bảng giá '!$B$22:$G$22,0))) -> Intra Metro | AF3: =AE3&" "&AC3 -> Intra Metro urban | AG3: 0.5 | AH3: 10 | AI3: 10 | AJ3: 10 | AK3: =AH3*AI3*AJ3/6000 -> 0.16666667 | AL3: =MAX(AK3,AG3) -> 0.5 | AM3: 31900 | AN3: INDEX('Bảng giá '!$A$2:$I$20,MATCH(AF3,'Bảng giá '!$A$2:$A$20,0),MATCH(MIN(CEILING(AL3,0.5),3),'Bảng giá '!$A$2:$I$2,0))+MAX(CEILING(AL3,0.5)-3,0)/0.5*VLOOKUP(AF3,'Bảng giá '!$A$2:$I$20,8,0) | AO3: =IF(LEFT(M3,3)="Trả",VLOOKUP(AF3,'Bảng giá '!$A$2:$I$20,9,0)*AN3,0) -> #VALUE! | AP3: 0 | AQ3: =AN3+AO3 -> #VALUE! | AR3: =_xlfn.IFNA(IF(AND(W3="Hà Nội",VLOOKUP(Z3,'Bảng giá '!$C$32:$D$35,2,0)="CK"),AN3*25%,0),_xlfn.IFNA(IF(AND(W3="HCM",VLOOKUP(Z3,'Bảng giá '!$C$36:$D$53,2,0)="CK"),AN3*25%,0),IF(AND(W3="Đà Nẵng",AD3="Khu Vực 2"),AN3*25%,0))) -> 0 | AS3: =AQ3-AR3 -> #VALUE! | AT3: =AS3*10% -> #VALUE! | AU3: =AS3+AT3 -> #VALUE! | BA3: =INDEX(check!$D$6:$F$7,MATCH(AUGUST!L3,check!$C$6:$C$7,0),MATCH(AUGUST!I3,check!$D$5:$F$5,0)) -> System Booking | BB3: =IF(AND(BA3="C2C Dropship",LEFT(Q3,4)="1297"),"B2C DropShip",IF(AND(BA3="C2C",LEFT(Q3,4)="1327"),"B2C DropShip",BA3)) -> System Booking
A4: SAMPLE | F4: =INT(DATE(YEAR(E4),MONTH(E4),DAY(E4))-DATE(YEAR(D4),MONTH(D4),DAY(D4))) -> 0 | G4: =IF(AND((LEFT(M4,4)="Giao"),F4<=VALUE(LEFT(P4,1))), "On time",IF(OR(LEFT(M4,3)="Trả",LEFT(M4,3)="Mất")," "," Late")) | I4: =IF(MID(K4,6,7)="AMSPICK","C-Return",IF(OR(LEFT(K4,5)="GHNTK",LEFT(K4,5)="GTKMP"),"Delivery","System Booking")) -> System Booking | J4: 589650928 | K4: 31428817219195 | L4: 1367 | M4: Trả thành công/Hoàn tất | N4: 1184000 | O4: 44179.434 | P4: 2 Ngày | Q4: 1058 - Bưu Cục 254-256 Âu Cơ-Q.Liên Chiểu-Đà Nẵng | R4: =IF(FIND("-",Q4,1)-1=5,VLOOKUP(REPLACE(Q4,1,7,""),'Bảng giá '!$Y:$AB,2,0),VLOOKUP(REPLACE(Q4,1,11,""),'Bảng giá '!$Y:$AB,2,0)) -> Quận Liên Chiểu - Đà Nẵng | S4: =VLOOKUP(R4,'Bảng giá '!$K:$Q,3,0) -> Đà Nẵng | T4: =VLOOKUP(R4,'Bảng giá '!$K:$Q,2,0) -> Quận Liên Chiểu | U4: =VLOOKUP(R4,'Bảng giá '!$K$1:$Q$768,6,0) -> North central | V4: =VLOOKUP(R4,'Bảng giá '!$K:$N,4,0) -> urban | W4: =VLOOKUP(R4,'Bảng giá '!$K:$Q,7,0) -> Đà Nẵng | X4: 25 Đào Trí, Phường Phú Thuận, Quận 7, Hồ Chí Minh | Y4: Quận Hải Châu - Đà Nẵng | Z4: =VLOOKUP(Y4,'Bảng giá '!$K$1:$M$768,3,0) -> Đà Nẵng | AA4: =VLOOKUP(Y4,'Bảng giá '!$K:$Q,2,0) -> Quận Hải Châu | AB4: =VLOOKUP(Y4,'Bảng giá '!$K$1:$Q$768,6,0) -> North central | AC4: =VLOOKUP(Y4,'Bảng giá '!K:N,4,0) -> urban | AD4: =VLOOKUP(Y4,'Bảng giá '!K:Q,7,0) -> Đà Nẵng | AE4: =IF(AND(S4=Y4,W4<>"HCM",W4<>"Hà Nội",W4<>"Đà Nẵng"),"Same Province",INDEX('Bảng giá '!$B$22:$G$28,MATCH(W4,'Bảng giá '!$A$22:$A$28,0),MATCH(AD4,'Bảng giá '!$B$22:$G$22,0))) -> Intra Metro | AF4: Far Region Suburban 2 | AG4: 1.1 | AH4: 10 | AI4: 10 | AJ4: 10 | AK4: =AH4*AI4*AJ4/6000 -> 0.16666667 | AL4: =MAX(AK4,AG4) -> 1.1 | AM4: 31900 | AN4: =INDEX('Bảng giá '!$A$2:$I$20,MATCH(AF4,'Bảng giá '!$A$2:$A$20,0),MATCH(MIN(CEILING(AL4,0.5),3),'Bảng giá '!$A$2:$I$2,0))+MAX(CEILING(AL4,0.5)-3,0)/0.5*VLOOKUP(AF4,'Bảng giá '!$A$2:$I$20,8,0) -> 47520 | AO4: =IF(LEFT(M4,3)="Trả",VLOOKUP(AF4,'Bảng giá '!$A$2:$I$20,9,0)*AN4,0) -> 19008 | AP4: 0 | AQ4: =AN4+AO4 -> 66528 | AR4: =_xlfn.IFNA(IF(AND(W4="Hà Nội",VLOOKUP(Z4,'Bảng giá '!$C$32:$D$35,2,0)="CK"),AN4*25%,0),_xlfn.IFNA(IF(AND(W4="HCM",VLOOKUP(Z4,'Bảng giá '!$C$36:$D$53,2,0)="CK"),AN4*25%,0),IF(AND(W4="Đà Nẵng",AD4="Khu Vực 2"),AN4*25%,0))) -> 0 | AS4: =AQ4-AR4 -> 66528 | AT4: =AS4*10% -> 6652.8 | AU4: =AS4+AT4 -> 73180.8 | BA4: =INDEX(check!$D$6:$F$7,MATCH(AUGUST!L4,check!$C$6:$C$7,0),MATCH(AUGUST!I4,check!$D$5:$F$5,0)) -> System Booking | BB4: =IF(AND(BA4="C2C Dropship",LEFT(Q4,4)="1297"),"B2C DropShip",IF(AND(BA4="C2C",LEFT(Q4,4)="1327"),"B2C DropShip",BA4)) -> System Booking
AN6: {=INDEX('Bảng giá '!A2:I20,MATCH(AUGUST!AF4,'Bảng giá '!A3:A20,0),MATCH(MIN(CEILING(AUGUST!AL4,0.5),3),'Bảng giá '!A2:I2,0)+MAX(CEILING(AUGUST!AL4,0.5)-3,0)/0.5*VLOOKUP(AUGUST!AF4,'Bảng giá '!A2:I20,8,0))} -> 47520 | AO6: =IF(LEFT(M4,3)="Trả",VLOOKUP(AF4,'Bảng giá '!A2:I20,9,0)*AUGUST!AN4,0) -> 19008
AO7: =IF(LEFT(M4,3)="Trả",VLOOKUP(AF4,'Bảng giá '!A2:I20,9,0)*AUGUST!AN4) -> 19008
Z8: nga | AA8: index('Bảng giá '!A2:I20,match(AUGUST!AF4,'Bảng giá '!A3:A20,0),match((min(ceiling(AUGUST!AG4,0.5),0),'Bảng giá '!A2:I2,0)+max(ceiling(AUGUST!AG4,0.5)-3,0)/0.5*vlookup(AUGUST!AF4,'Bảng giá '!A2:I20,8,0))) | AN8: =CEILING(AL4,0.5) -> 1.5
AA11: INDEX('Bảng giá '!$A$2:$I$20,MATCH(AF3,'Bảng giá '!$A$2:$A$20,0),MATCH(MIN(CEILING(AL3,0.5),3),'Bảng giá '!$A$2:$I$2,0))+MAX(CEILING(AL3,0.5)-3,0)/0.5*VLOOKUP(AF3,'Bảng giá '!$A$2:$I$20,8,0)

Sheet Bảng giá 
A1: Bảng Giá Dịch Vụ Chuyển Phát | K1: Quận/Huyện - Tỉnh/TP | L1: Quận/Huyện | M1: Tỉnh/TP | N1: Urban | O1: Miền Tây or NOT | P1: Area | Q1: Khu Vực | S1: Tỉnh - Thành phố | T1: Khu Vực | V1: ID kho | W1: Tên KL cũ | X1: Tên KL hiện tại | Y1: Tên KL mới | Z1: Quận/Huyện | AA1: Tỉnh | AB1: Khu vực | AD1: Kho Lấy Cũ | AE1: Khu Vực
A2: Định Danh/Số Kg | B2: 0.5 | C2: 1 | D2: 1.5 | E2: 2 | F2: 2.5 | G2: 3 | H2: Thêm 0.5 | I2: Cước Trả | K2: Quận Đặc Biệt - Hà Nội | L2: Quận Đặc Biệt | M2: Hà Nội | N2: urban | O2: NOT | P2: North | Q2: Hà Nội | S2: An Giang | T2: Khu vực 1 | V2: 1454 | W2: Kho giao nhận Ngã Bảy_Hậu Giang | X2: Bưu Cục 01 Châu Văn Liêm | Y2: Bưu Cục 01 Châu Văn Liêm-Ngã Bảy-Hậu Giang | Z2: Thị xã Ngã Bảy - Hậu Giang | AA2: Hậu Giang | AB2: Khu Vực 1 | AD2: Bưu Cục 21 Đặng Văn Ngữ | AE2: Đà Nẵng
A3: Intra Metro Urban | B3: 11340 | C3: 11340 | D3: 11340 | E3: 11340 | F3: 11340 | G3: 11340 | H3: 1418 | I3: 0 | K3: Quận Đặc Biệt - Hưng Yên | L3: Quận Đặc Biệt | M3: Hưng Yên | N3: urban | O3: NOT | P3: North | Q3: Khu Vực 3 | S3: Bà Rịa Vũng Tàu | T3: Khu vực 1 | V3: 1192 | W3: Kho giao nhận Phan Rang_Ninh Thuận | X3: Bưu Cục 01 Lương Văn Can 1 | Y3: Bưu Cục Phan Rang-Ninh Thuận | Z3: Thành phố Phan Rang - Tháp Chàm - Ninh Thuận | AA3: Ninh Thuận | AB3: Khu Vực 1 | AD3: Bưu Cục 254 - 256 Âu Cơ | AE3: Đà Nẵng
A4: Intra Metro Suburban 1 | B4: 13230 | C4: 13230 | D4: 13230 | E4: 13230 | F4: 13230 | G4: 13230 | H4: 1418 | I4: 0 | K4: Quận Đặc Biệt DC - Hồ Chí Minh | L4: Quận Đặc Biệt DC | M4: Hồ Chí Minh | N4: urban | O4: NOT | P4: South | Q4: HCM | S4: Bắc Giang | T4: Khu vực 3 | V4: 1961 | W4: Kho giao nhận Thuận Nam_Ninh Thuận | X4: Bưu Cục 01 Lương Văn Can 2 | Y4: Bưu Cục Thuận Nam-Ninh Thuận | Z4: Thành phố Phan Rang - Tháp Chàm - Ninh Thuận | AA4: Ninh Thuận | AB4: Khu Vực 1 | AD4: Bưu Cục 350 Ngũ Hành Sơn | AE4: Đà Nẵng
A5: Intra Metro Suburban 2 | B5: 15120 | C5: 15120 | D5: 15120 | E5: 15120 | F5: 15120 | G5: 15120 | H5: 1418 | I5: 0 | K5: Quận Cẩm Lệ - Đà Nẵng | L5: Quận Cẩm Lệ | M5: Đà Nẵng | N5: urban | O5: NOT | P5: North central | Q5: Đà Nẵng | S5: Bắc Kạn | T5: Khu vực 3 | V5: 1126 | W5: Kho giao nhận Đồng Hới_Quảng Bình | X5: Bưu Cục 01 Tây Sơn | Y5: Bưu Cục 01 Tây Sơn-Đồng Hới-Quảng Bình | Z5: Thành phố đồng hới - Quảng Bình | AA5: Quảng Bình | AB5: Khu Vực 2 | AD5: Bưu Cục 77 Nguyễn Phước Thái | AE5: Đà Nẵng
A6: Same Region Urban | B6: 13500 | C6: 13500 | D6: 13500 | E6: 13500 | F6: 13500 | G6: 13500 | H6: 1500 | I6: 0.4 | K6: Quận Hải Châu - Đà Nẵng | L6: Quận Hải Châu | M6: Đà Nẵng | N6: urban | O6: NOT | P6: North central | Q6: Đà Nẵng | S6: Bạc Liêu | T6: Khu vực 1 | V6: 2323 | W6: Kho giao nhận Yên Minh_Hà Giang | X6: Bưu Cục 02 Lê Quý Đôn | Y6: Bưu Cục 02 Lê Quý Đôn-Yên Minh-Hà Giang | Z6: Huyện Yên Minh - Hà Giang | AA6: Hà Giang | AB6: Khu Vực 3 | AD6: Bưu Cục Hòa Vang | AE6: Đà Nẵng
A7: Same Region Suburban 1 | B7: 17250 | C7: 17250 | D7: 17250 | E7: 17250 | F7: 17250 | G7: 17250 | H7: 1500 | I7: 0.4 | K7: Quận Liên Chiểu - Đà Nẵng | L7: Quận Liên Chiểu | M7: Đà Nẵng | N7: urban | O7: NOT | P7: North central | Q7: Đà Nẵng | S7: Bắc Ninh | T7: Khu vực 3 | V7: 1113 | W7: Kho giao nhận Thái Bình_Thái Bình | X7: Bưu Cục 2 Lý Thái Tổ | Y7: Bưu Cục 02 Lý Thái Tổ-TP.Thái Bình | Z7: thành phố Thái Bình - Thái Bình | AA7: Thái Bình | AB7: Khu Vực 3 | AD7: Kho Trung Chuyển Đà Nẵng | AE7: Đà Nẵng
A8: Same Region Suburban 2 | B8: 17250 | C8: 17250 | D8: 17250 | E8: 17250 | F8: 17250 | G8: 17250 | H8: 1500 | I8: 0.4 | K8: Quận Ngũ Hành Sơn - Đà Nẵng | L8: Quận Ngũ Hành Sơn | M8: Đà Nẵng | N8: urban | O8: NOT | P8: North central | Q8: Đà Nẵng | S8: Bến Tre | T8: Khu vực 1 | V8: 1333 | W8: Kho giao nhận Bình Chánh_Hồ Chí Minh | X8: Bưu Cục 2 Nguyễn Hới | Y8: Bưu Cục Tân Kiên-Bình Chánh-HCM | Z8: Huyện Bình Chánh - Hồ Chí Minh | AA8: Hồ Chí Minh | AB8: HCM | AD8: Bưu Cục 107 Nguyễn Chí Thanh | AE8: Hà Nội
A9: Near Region Urban | B9: 13500 | C9: 13500 | D9: 13500 | E9: 13500 | F9: 13500 | G9: 13500 | H9: 1500 | I9: 0.4 | K9: Quận Sơn Trà - Đà Nẵng | L9: Quận Sơn Trà | M9: Đà Nẵng | N9: urban | O9: NOT | P9: North central | Q9: Đà Nẵng | S9: Bình Định | T9: Khu vực 1 | V9: 1072 | W9: Kho giao nhận Nha Trang_Khánh Hòa | X9: Bưu Cục 3 Cù Chính Lan | Y9: Bưu Cục 03 Cù Chính Lan-Nha Trang-Khánh Hòa | Z9: Thành Phố Nha Trang - Khánh Hòa | AA9: Khánh Hòa | AB9: Khu Vực 1 | AD9: Bưu Cục 108 Kim Bài | AE9: Hà Nội
A10: Near Region Suburban 1 | B10: 17250 | C10: 17250 | D10: 17250 | E10: 17250 | F10: 17250 | G10: 17250 | H10: 1500 | I10: 0.4 | K10: Quận Thanh Khê - Đà Nẵng | L10: Quận Thanh Khê | M10: Đà Nẵng | N10: urban | O10: NOT | P10: North central | Q10: Đà Nẵng | S10: Bình Dương | T10: Khu vực 1 | V10: 2439 | W10: Kho giao nhận Phường 13-Tân Bình_Hồ Chí Minh | X10: Bưu Cục 4 Nhất Chi Mai | Y10: Bưu Cục 04 Nhất Chi Mai-Q.Tân Bình-HCM | Z10: Quận Tân Bình - Hồ Chí Minh | AA10: Hồ Chí Minh | AB10: HCM | AD10: Bưu Cục 114 Yên Lãng | AE10: Hà Nội
A11: Near Region Suburban 2 | B11: 17250 | C11: 17250 | D11: 17250 | E11: 17250 | F11: 17250 | G11: 17250 | H11: 1500 | I11: 0.4 | K11: Huyện Hòa Vang - Đà Nẵng | L11: Huyện Hòa Vang | M11: Đà Nẵng | N11: suburban 2 | O11: NOT | P11: North central | Q11: Đà Nẵng | S11: Bình Phước | T11: Khu vực 1 | V11: 1326 | W11: Kho giao nhận Quận 9_Hồ Chí Minh | X11: Bưu Cục Số 5 Đường 8 | Y11: Bưu cục 285A Nguyễn Văn Tăng-Q.9-HCM | Z11: Quận 9 - Hồ Chí Minh | AA11: Hồ Chí Minh | AB11: HCM | AD11: Bưu Cục 124 Phan Bá Vành | AE11: Hà Nội
A12: Special Lane Urban | B12: 27000 | C12: 38700 | D12: 50400 | E12: 62100 | F12: 73800 | G12: 85500 | H12: 6000 | I12: 0.4 | K12: Quận Ba Đình - Hà Nội | L12: Quận Ba Đình | M12: Hà Nội | N12: urban | O12: NOT | P12: North | Q12: Hà Nội | S12: Bình Thuận | T12: Khu vực 1 | V12: 1407 | W12: Kho giao nhận Kiên Lương_Kiên Giang | X12: Bưu Cục 5 Huyền Trân Công Chúa | Y12: Bưu Cục 05 Huyền Trân Công Chúa-Kiên Lương-Kiên Giang | Z12: Huyện Kiên Lương - Kiên Giang | AA12: Kiên Giang | AB12: Khu Vực 1 | AD12: Bưu Cục 124 Trịnh Văn Bô | AE12: Hà Nội
A13: Special Lane Suburban 1 | B13: 29700 | C13: 41400 | D13: 53100 | E13: 64800 | F13: 76500 | G13: 88200 | H13: 6000 | I13: 0.4 | K13: Quận Cầu Giấy - Hà Nội | L13: Quận Cầu Giấy | M13: Hà Nội | N13: urban | O13: NOT | P13: North | Q13: Hà Nội | S13: Cà Mau | T13: Khu vực 1 | V13: 1065 | W13: Kho giao nhận Thủ Dầu Một_Bình Dương | X13: Bưu Cục 08 Ba Mươi Tháng Tư 1 | Y13: Bưu Cục 08 Ba Mươi Tháng Tư-Thủ Dầu Một-Bình Dương 01 | Z13: Thành Phố Thủ Dầu Một - Bình Dương | AA13: Bình Dương | AB13: Khu Vực 1 | AD13: Bưu Cục 129T Nguyễn Trãi | AE13: Hà Nội
A14: Special Lane Suburban 2 | B14: 29700 | C14: 41400 | D14: 53100 | E14: 64800 | F14: 76500 | G14: 88200 | H14: 6000 | I14: 0.4 | K14: Quận Đống Đa - Hà Nội | L14: Quận Đống Đa | M14: Hà Nội | N14: urban | O14: NOT | P14: North | Q14: Hà Nội | S14: Cần Thơ | T14: Khu vực 1 | V14: 2418 | W14: Kho giao nhận Hiệp Thành_Bình Dương | X14: Bưu Cục 08 Ba Mươi Tháng Tư 2 | Y14: Bưu Cục 08 Ba Mươi Tháng Tư-Thủ Dầu Một-Bình Dương 02 | Z14: Thành phố Thủ Dầu Một - Bình Dương | AA14: Bình Dương | AB14: Khu Vực 1 | AD14: Bưu Cục 16 Tiền Huân | AE14: Hà Nội
... A20: Same Province Suburban 2 | B20: 15120 | C20: 15120 | D20: 15120 | E20: 15120 | F20: 15120 | G20: 15120 | H20: 1418 | I20: 0 | K20: Quận Tây Hồ - Hà Nội | L20: Quận Tây Hồ | M20: Hà Nội | N20: urban | O20: NOT | P20: North | Q20: Hà Nội | S20: Đồng Nai | T20: Khu vực 1 | V20: 2308 | W20: Kho giao nhận Krông Pắc_Đắk Lắk | X20: Bưu Cục 10 Trần Hưng Đạo | Y20: Bưu Cục 10 Trần Hưng Đạo-Krông Pắc-Đắk Lắk | Z20: Huyện Krông Pắc - Đắk Lắk | AA20: Đắk Lắk | AB20: Khu Vực 1 | AD20: Bưu Cục 188 Nguyễn Ngọc Nại | AE20: Hà Nội
K21: Quận Thanh Xuân - Hà Nội | L21: Quận Thanh Xuân | M21: Hà Nội | N21: urban | O21: NOT | P21: North | Q21: Hà Nội | S21: Đồng Tháp | T21: Khu vực 1 | V21: 1213 | W21: Kho giao nhận Bắc Giang_Bắc Giang | X21: Bưu Cục 100 Giáp Hải | Y21: Bưu Cục 100 Giáp Hải-TP.Bắc Giang | Z21: Thành Phố Bắc Giang - Bắc Giang | AA21: Bắc Giang | AB21: Khu Vực 3 | AD21: Bưu Cục 211 Lạc long Quân | AE21: Hà Nội
A22: Tuyến | B22: HCM | C22: Đà Nẵng | D22: Hà Nội | E22: Khu Vực 1 | F22: Khu Vực 2 | G22: Khu Vực 3 | K22: Quận Từ Liêm - Hà Nội | L22: Quận Từ Liêm | M22: Hà Nội | N22: suburban 1 | O22: NOT | P22: North | Q22: Hà Nội | S22: Gia Lai | T22: Khu vực 1 | V22: 1139 | W22: Kho giao nhận Phủ Lý_Hà Nam | X22: Bưu Cục 101B Lý Thái Tổ | Y22: Bưu Cục 101B Lý Thái Tổ-Phủ Lý-Hà Nam | Z22: thành phố Phủ Lý - Hà Nam | AA22: Hà Nam | AB22: Khu Vực 3 | AD22: Bưu Cục 221 Kim Ngưu | AE22: Hà Nội
A23: HCM | B23: Intra Metro | C23: Special Lane | D23: Special Lane | E23: Same Region | F23: Near Region | G23: Far Region | K23: Quận Bắc Từ Liêm - Hà Nội | L23: Quận Bắc Từ Liêm | M23: Hà Nội | N23: suburban 1 | O23: NOT | P23: North | Q23: Hà Nội | S23: Hà Giang | T23: Khu vực 3 | V23: 1487 | W23: KV3 Bưu cục 120 Hoàng Liên - Lào Cai | X23: Bưu Cục 102 Hoàng Liên | Y23: Bưu Cục 102 Hoàng Liên-TP.Lào Cai | Z23: Thành Phố Lào Cai - Lào Cai | AA23: Lào Cai | AB23: Khu Vực 3 | AD23: Bưu Cục 23 ngõ 164 Ỷ La | AE23: Hà Nội
A24: Đà Nẵng | B24: Special Lane | C24: Intra Metro | D24: Special Lane | E24: Near Region | F24: Same Region | G24: Near Region | K24: Quận Nam Từ Liêm - Hà Nội | L24: Quận Nam Từ Liêm | M24: Hà Nội | N24: suburban 1 | O24: NOT | P24: North | Q24: Hà Nội | S24: Hà Nam | T24: Khu vực 3 | V24: 1165 | W24: Kho giao nhận Thái Nguyên_Thái Nguyên | X24: Bưu Cục 83 Thanh Niên Xung Phong | Y24: Bưu Cục 83 Thanh Niên Xung Phong-TP.Thái Nguyên | Z24: Thành phố Thái Nguyên - Thái Nguyên | AA24: Thái Nguyên | AB24: Khu Vực 3 | AD24: Bưu Cục 25 Trương Định 1 | AE24: Hà Nội
A25: Hà Nội | B25: Special Lane | C25: Special Lane | D25: Intra Metro | E25: Far Region | F25: Near Region | G25: Same Region | K25: Huyện Gia Lâm - Hà Nội | L25: Huyện Gia Lâm | M25: Hà Nội | N25: suburban 2 | O25: NOT | P25: North | Q25: Hà Nội | S25: Hà Nội | T25: Hà Nội | V25: 2389 | W25: Kho giao nhận Láng Thượng_Hà Nội | X25: Bưu Cục 107 Nguyễn Chí Thanh | Y25: Bưu Cục 107 Nguyễn Chí Thanh-Q.Đống Đa-HN | Z25: Quận Đống Đa - Hà Nội | AA25: Hà Nội | AB25: Hà Nội | AD25: Bưu Cục 25 Trương Định 2 | AE25: Hà Nội
A26: Khu Vực 1 | B26: Same Region | C26: Near Region | D26: Far Region | E26: Same Region | F26: Near Region | G26: Far Region | K26: Huyện Ba Vì - Hà Nội | L26: Huyện Ba Vì | M26: Hà Nội | N26: suburban 2 | O26: NOT | P26: North | Q26: Hà Nội | S26: Hà Tĩnh | T26: Khu vực 3 | V26: 2398 | W26: Kho giao nhận Văn Yên_Yên Bái | X26: Bưu Cục 107 Trần Hưng Đạo | Y26: Bưu Cục 107 Trần Hưng Đạo-Văn Yên-Yên Bái | Z26: Huyện Văn Yên - Yên Bái | AA26: Yên Bái | AB26: Khu Vực 3 | AD26: Bưu Cục 263 Phố Vọng | AE26: Hà Nội
A27: Khu Vực 2 | B27: Near Region | C27: Same Region | D27: Near Region | E27: Near Region | F27: Same Region | G27: Near Region | K27: Huyện Đan Phượng - Hà Nội | L27: Huyện Đan Phượng | M27: Hà Nội | N27: suburban 2 | O27: NOT | P27: North | Q27: Hà Nội | S27: Hải Dương | T27: Khu vực 3 | V27: 1581 | W27: HN Bưu cục 108 Kim Bài - Hà Nội | X27: Bưu Cục 108 Kim Bài | Y27: Bưu Cục 108 Kim Bài-Thanh Oai-HN | Z27: Huyện thanh oai - Hà Nội | AA27: Hà Nội | AB27: Hà Nội | AD27: Bưu Cục 275 Khâm Thiên | AE27: Hà Nội
A28: Khu Vực 3 | B28: Far Region | C28: Near Region | D28: Same Region | E28: Far Region | F28: Near Region | G28: Same Region | K28: Huyện Đông Anh - Hà Nội | L28: Huyện Đông Anh | M28: Hà Nội | N28: suburban 2 | O28: NOT | P28: North | Q28: Hà Nội | S28: Hải Phòng | T28: Khu vực 3 | V28: 1215 | W28: Kho giao nhận Hưng Yên_Hưng Yên | X28: Bưu Cục 11 Chu Mạnh Trinh | Y28: Bưu Cục 11 Chu Mạnh Trinh-TP.Hưng Yên | Z28: Thành Phố Hưng Yên - Hưng Yên | AA28: Hưng Yên | AB28: Khu Vực 3 | AD28: Bưu Cục 299 Trung Kính | AE28: Hà Nội
K29: Huyện Ba Vì - Hà Nội | L29: Huyện Ba Vì | M29: Hà Nội | N29: suburban 2 | O29: NOT | P29: North | Q29: Hà Nội | S29: Hậu Giang | T29: Khu vực 1 | V29: 1319 | W29: Kho giao nhận Trảng Bom_Đồng Nai | X29: Bưu Cục 110 Nguyễn Huệ | Y29: Bưu Cục 110 Nguyễn Huệ-Trảng Bom-Đồng Nai | Z29: Huyện Trảng Bom - Đồng Nai | AA29: Đồng Nai | AB29: Khu Vực 1 | AD29: Bưu Cục 325 Trần Cung | AE29: Hà Nội
A30: Từ Tỉnh | B30: Tỉnh-Tỉnh | C30: Đến Tỉnh | D30: Chiết khấu | F30: Định Nghĩa Tuyến | K30: Huyện Đan Phượng - Hà Nội | L30: Huyện Đan Phượng | M30: Hà Nội | N30: suburban 2 | O30: NOT | P30: North | Q30: Hà Nội | S30: Hồ Chí Minh | T30: Hồ Chí Minh | V30: 1135 | W30: Kho giao nhận Ninh Bình_Ninh Bình | X30: Bưu Cục 111 Xuân Thành 1 | Y30: Bưu Cục 111 Xuân Thành-Ninh Bình-Ninh Bình 01 | Z30: Thành phố Ninh Bình - Ninh Bình | AA30: Ninh Bình | AB30: Khu Vực 3 | AD30: Bưu Cục 397 Nguyễn Khang | AE30: Hà Nội
A31: Đà Nẵng | B31: =A31&" - "&C31 -> Đà Nẵng - Khu Vực 2 | C31: Khu Vực 2 | D31: CK | F31: Tuyến | G31: Route Hợp Đồng | H31: Route Tiki | K31: Huyện Đông Anh - Hà Nội | L31: Huyện Đông Anh | M31: Hà Nội | N31: suburban 2 | O31: NOT | P31: North | Q31: Hà Nội | S31: Hòa Bình | T31: Khu vực 3 | V31: 1546 | W31: KV3 Bưu cục 130 Đinh Tiên Hoàng - Ninh Bình | X31: Bưu Cục 111 Xuân Thành 2 | Y31: Bưu Cục 111 Xuân Thành-Ninh Bình-Ninh Bình 02 | Z31: Thành phố Ninh Bình - Ninh Bình | AA31: Ninh Bình | AB31: Khu Vực 3 | AD31: Bưu Cục 464 Âu Cơ | AE31: Hà Nội
A32: Hà Nội | B32: =A32&" - "&C32 -> Hà Nội - Nghệ An | C32: Nghệ An | D32: CK | F32: Same Province | G32: HN <-> HN ĐN <-> ĐN HCM <-> HCM Tỉnh X KVY <-> Tỉnh X KVY | H32: Same Province | K32: Huyện Hoài Đức - Hà Nội | L32: Huyện Hoài Đức | M32: Hà Nội | N32: suburban 2 | O32: NOT | P32: North | Q32: Hà Nội | S32: Hưng Yên | T32: Khu vực 3 | V32: 1525 | W32: KV3 Bưu cục 113 Quang Trung - Bắc Giang | X32: Bưu Cục 113 Quang Trung | Y32: Bưu Cục 113 Quang Trung-TP.Bắc Giang | Z32: Thành Phố Bắc Giang - Bắc Giang | AA32: Bắc Giang | AB32: Khu Vực 3 | AD32: Bưu Cục 482 Đội Cấn | AE32: Hà Nội
A33: Hà Nội | B33: =A33&" - "&C33 -> Hà Nội - Thanh Hóa | C33: Thanh Hóa | D33: CK | F33: Same Region 1 | G33: ĐN <-> KV2 | H33: Same Region 1 | K33: Huyện Mê Linh - Hà Nội | L33: Huyện Mê Linh | M33: Hà Nội | N33: suburban 2 | O33: NOT | P33: North | Q33: Hà Nội | S33: Khánh Hòa | T33: Khu vực 1 | V33: 1352 | W33: HN Bưu cục 114 Yên Lãng - Hà Nội | X33: Bưu Cục 114 Yên Lãng | Y33: Bưu Cục 114 Yên Lãng-Q.Đống Đa-HN | Z33: Quận Đống Đa - Hà Nội | AA33: Hà Nội | AB33: Hà Nội | AD33: Bưu Cục 51 Tây Đằng | AE33: Hà Nội
A34: Hà Nội | B34: =A34&" - "&C34 -> Hà Nội - Sơn La | C34: Sơn La | D34: CK | F34: Same Region 2 | G34: HN <-> KV3 HCM <-> KV1 KV3 <-> KV3 KV2 <-> KV2 KV1 <-> KV1 | H34: Same Region 2 | K34: Huyện Mỹ Đức - Hà Nội | L34: Huyện Mỹ Đức | M34: Hà Nội | N34: suburban 2 | O34: NOT | P34: North | Q34: Hà Nội | S34: Kiên Giang | T34: Khu vực 1 | V34: 1074 | W34: Kho giao nhận Buôn Mê Thuột_Đắk Lắk | X34: Bưu Cục 116 Hoàng Hoa Thám 1 | Y34: Bưu Cục 116 Hoàng Hoa Thám-Buôn Ma Thuột-Đắk Lắk | Z34: Thành phố Buôn Ma Thuột - Đắk Lắk | AA34: Đắk Lắk | AB34: Khu Vực 1 | AD34: Bưu Cục 54 Nguyễn Văn Hưởng | AE34: Hà Nội
A35: Hà Nội | B35: =A35&" - "&C35 -> Hà Nội - Hà Tĩnh | C35: Hà Tĩnh | D35: CK | F35: Special Cross- Region | G35: HN <-> ĐN <-> HCM <-> HN | H35: Speccial Cross- Region | K35: Huyện Phúc Thọ - Hà Nội | L35: Huyện Phúc Thọ | M35: Hà Nội | N35: suburban 2 | O35: NOT | P35: North | Q35: Hà Nội | S35: Kon Tum | T35: Khu vực 1 | V35: 1930 | W35: Kho giao nhận Buôn Đôn_Đắk Lắk | X35: Bưu Cục 116 Hoàng Hoa Thám 2 | Y35: Bưu Cục Buôn Đôn-Đắk Lắk | Z35: Thành phố Buôn Ma Thuột - Đắk Lắk | AA35: Đắk Lắk | AB35: Khu Vực 1 | AD35: Bưu Cục 54 Thạch Cầu | AE35: Hà Nội
A36: Hồ Chí Minh | B36: =A36&" - "&C36 -> Hồ Chí Minh - Bình Định | C36: Bình Định | D36: CK | F36: Cross Region | G36: HN <-> KV1, KV2 ĐN <-> KV1, KV3 HCM <-> KV2, KV3 KV3 <-> KV1, KV2 KV2 <-> KV1, KV3 KV1 <-> KV2, KV3 | H36: Cross- Region | K36: Huyện Sóc Sơn - Hà Nội | L36: Huyện Sóc Sơn | M36: Hà Nội | N36: suburban 2 | O36: NOT | P36: North | Q36: Hà Nội | S36: Lai Châu | T36: Khu vực 3 | V36: 1486 | W36: KV3 Bưu cục 119 Hùng Vương - Vĩnh Yên | X36: Bưu Cục 119 Hùng Vương | Y36: Bưu Cục 119 Hùng Vương-Vĩnh Yên-Vĩnh Phúc | Z36: Thành phố Vĩnh Yên - Vĩnh Phúc | AA36: Vĩnh Phúc | AB36: Khu Vực 3 | AD36: Bưu Cục 551 Quang Trung | AE36: Hà Nội
A37: Hồ Chí Minh | B37: =A37&" - "&C37 -> Hồ Chí Minh - Đắk Lắk | C37: Đắk Lắk | D37: CK | K37: Huyện Thạch Thất - Hà Nội | L37: Huyện Thạch Thất | M37: Hà Nội | N37: suburban 2 | O37: NOT | P37: North | Q37: Hà Nội | S37: Lâm Đồng | T37: Khu vực 1 | V37: 1418 | W37: HCM Bưu cục 55 Nguyễn Văn Luông - Hồ Chí Minh | X37: Bưu Cục 119 Nguyễn Văn Luông | Y37: Bưu Cục 119 Nguyễn Văn Luông-Q.6-HCM | Z37: Quận 6 - Hồ Chí Minh | AA37: Hồ Chí Minh | AB37: HCM | AD37: Bưu Cục 57 Hạ Đình | AE37: Hà Nội
A38: Hồ Chí Minh | B38: =A38&" - "&C38 -> Hồ Chí Minh - Kiên Giang | C38: Kiên Giang | D38: CK | K38: Huyện Thanh Oai - Hà Nội | L38: Huyện Thanh Oai | M38: Hà Nội | N38: suburban 2 | O38: NOT | P38: North | Q38: Hà Nội | S38: Lạng Sơn | T38: Khu vực 3 | V38: 1236 | W38: Kho giao nhận Ô Môn_Cần Thơ | X38: Bưu Cục 1190 QL91 | Y38: Bưu Cục 1190 QL91-Q.Ô Môn-Cần Thơ | Z38: Quận Ô Môn - Cần Thơ | AA38: Cần Thơ | AB38: Khu Vực 1 | AD38: Bưu Cục 6/318 Ngọc Trì | AE38: Hà Nội
A39: Hồ Chí Minh | B39: =A39&" - "&C39 -> Hồ Chí Minh - Khánh Hòa | C39: Khánh Hòa | D39: CK | K39: Huyện Thanh Trì - Hà Nội | L39: Huyện Thanh Trì | M39: Hà Nội | N39: suburban 2 | O39: NOT | P39: North | Q39: Hà Nội | S39: Lào Cai | T39: Khu vực 3 | V39: 2301 | W39: Kho giao nhận Tháp Mười_Đồng Tháp | X39: Bưu Cục 12 Bà Triệu | Y39: Bưu Cục Tháp Mười-Đồng Tháp | Z39: Huyện Tháp Mười - Đồng Tháp | AA39: Đồng Tháp | AB39: Khu Vực 1 | AD39: Bưu Cục 644 Nguyễn Văn Cừ | AE39: Hà Nội
A40: Hồ Chí Minh | B40: =A40&" - "&C40 -> Hồ Chí Minh - An Giang | C40: An Giang | D40: CK | K40: Huyện Ứng Hòa - Hà Nội | L40: Huyện Ứng Hòa | M40: Hà Nội | N40: suburban 2 | O40: NOT | P40: North | Q40: Hà Nội | S40: Long An | T40: Khu vực 1 | V40: 1385 | W40: Kho giao nhận Hồng Lĩnh_Hà Tĩnh | X40: Bưu Cục 12 Ngõ 340 Quang Trung | Y40: Bưu Cục 12 Ngõ 340 Quang Trung-Hồng Lĩnh-Hà Tĩnh | Z40: Thị Xã Hồng Lĩnh - Hà Tĩnh | AA40: Hà Tĩnh | AB40: Khu Vực 3 | AD40: Bưu Cục 8 Đình Nguyên | AE40: Hà Nội
A41: Hồ Chí Minh | B41: =A41&" - "&C41 -> Hồ Chí Minh - Gia Lai | C41: Gia Lai | D41: CK | K41: Thị xã Sơn Tây - Hà Nội | L41: Thị xã Sơn Tây | M41: Hà Nội | N41: suburban 2 | O41: NOT | P41: North | Q41: Hà Nội | S41: Nam Định | T41: Khu vực 3 | V41: 1567 | W41: KV3 Bưu cục 12 Trần Nhân Tông - Uông Bí | X41: Bưu Cục 12 Trần Nhân Tông | Y41: Bưu Cục 12 Trần Nhân Tông-Uông Bí-Quảng Ninh | Z41: Thành Phố Uông Bí - Quảng Ninh | AA41: Quảng Ninh | AB41: Khu Vực 3 | AD41: Bưu Cục 88 Nguyễn Khánh Toàn | AE41: Hà Nội
A42: Hồ Chí Minh | B42: =A42&" - "&C42 -> Hồ Chí Minh - Phú Yên | C42: Phú Yên | D42: CK | K42: Huyện Chương Mỹ - Hà Nội | L42: Huyện Chương Mỹ | M42: Hà Nội | N42: suburban 2 | O42: NOT | P42: North | Q42: Hà Nội | S42: Nghệ An | T42: Khu vực 3 | V42: 1083 | W42: Kho giao nhận Cao Lãnh_Đồng Tháp | X42: Bưu Cục 12-14 Bà Triệu 1 | Y42: Bưu Cục 12-14 Bà Triệu-Cao Lãnh-Đồng Tháp | Z42: Thành phố Cao Lãnh - Đồng Tháp | AA42: Đồng Tháp | AB42: Khu Vực 1 | AD42: Bưu Cục 97 Thiên Hiền | AE42: Hà Nội
A43: Hồ Chí Minh | B43: =A43&" - "&C43 -> Hồ Chí Minh - Tây Ninh | C43: Tây Ninh | D43: CK | K43: Huyện Quốc Oai - Hà Nội | L43: Huyện Quốc Oai | M43: Hà Nội | N43: suburban 2 | O43: NOT | P43: North | Q43: Hà Nội | S43: Ninh Bình | T43: Khu vực 3 | V43: 1397 | W43: Kho giao nhận Nhơn Trạch_Đồng Nai | X43: Bưu Cục 124 Lý Thái Tổ 1 | Y43: Bưu Cục 124 Lý Thái Tổ-Nhơn Trạch-Đồng Nai 01 | Z43: Huyện Nhơn Trạch - Đồng Nai | AA43: Đồng Nai | AB43: Khu Vực 1 | AD43: Bưu Cục Đông Anh | AE43: Hà Nội
A44: Hồ Chí Minh | B44: =A44&" - "&C44 -> Hồ Chí Minh - Ninh Thuận | C44: Ninh Thuận | D44: CK | K44: Huyện Quốc Oai - Hà Nội | L44: Huyện Quốc Oai | M44: Hà Nội | N44: suburban 2 | O44: NOT | P44: North | Q44: Hà Nội | S44: Ninh Thuận | T44: Khu vực 1 | V44: 2430 | W44: Kho giao nhận Phú Thạnh-Nhơn Trạch_Đồng Nai | X44: Bưu Cục 124 Lý Thái Tổ 2 | Y44: Bưu Cục 124 Lý Thái Tổ-Nhơn Trạch-Đồng Nai 02 | Z44: Huyện Nhơn Trạch - Đồng Nai | AA44: Đồng Nai | AB44: Khu Vực 1 | AD44: Bưu Cục Hoài Đức | AE44: Hà Nội
A45: Hồ Chí Minh | B45: =A45&" - "&C45 -> Hồ Chí Minh - Tiền Giang | C45: Tiền Giang | D45: CK | K45: Huyện Thường Tín - Hà Nội | L45: Huyện Thường Tín | M45: Hà Nội | N45: suburban 2 | O45: NOT | P45: North | Q45: Hà Nội | S45: Phú Thọ | T45: Khu vực 3 | V45: 1313 | W45: Kho giao nhận Bắc Từ Liêm_Hà Nội | X45: Bưu Cục 124 Phan Bá Vành | Y45: Bưu Cục 124 Phan Bá Vành-Q.Bắc Từ Liêm-HN | Z45: Quận Bắc Từ Liêm - Hà Nội | AA45: Hà Nội | AB45: Hà Nội | AD45: Kho Khách hàng lớn Hà Nội | AE45: Hà Nội
...

Sheet check
D5: Delivery | E5: C-Return | F5: System Booking
C6: 1367 | D6: B2C Non - Dropship | E6: C-Return | F6: System Booking
C7: 2590595 | D7: C2C Dropship | E7: C-Return | F7: System Booking
C12: Tuyến | D12: Thời gian giao hàng cam kết | G12: Thời gian cam kết trả hàng | H12: Thời gian Toàn Trình | L12: TIKI | M12: Tuyến | N12: HCM | O12: Đà Nẵng | P12: Hà Nội | Q12: Khu vực 1 | R12: Khu vực 2 | S12: Khu vực 3
D13: urban | E13: suburban 1 | F13: suburban 2 | M13: HCM | N13: Intra Metro | O13: Special Lane | P13: Special Lane | Q13: Same Region | R13: Near Region | S13: Far Region
C14: Intra Metro | D14: 1 | E14: 1 | F14: 1 | G14: 2 | H14: 8 | M14: Đà Nẵng | N14: Special Lane | O14: Intra Metro | P14: Special Lane | Q14: Near Region | R14: Same Region | S14: Near Region
C15: Same Province | D15: 1 | E15: 1 | F15: 2 | G15: 3 | H15: 9 | M15: Hà Nội | N15: Special Lane | O15: Special Lane | P15: Intra Metro | Q15: Far Region | R15: Near Region | S15: Same Region
C16: Same Region | D16: 1 | E16: 1 | F16: 2 | G16: 4 | H16: 10 | M16: Khu vực 1 | N16: Same Region | O16: Near Region | P16: Far Region | Q16: Same Region | R16: Near Region | S16: Far Region
C17: Near Region | D17: 2 | E17: 2 | F17: 3 | G17: 5 | H17: 12 | M17: Khu vực 2 | N17: Near Region | O17: Same Region | P17: Near Region | Q17: Near Region | R17: Same Region | S17: Near Region
C18: Far Region | D18: 3 | E18: 3 | F18: 4 | G18: 5 | H18: 14 | M18: Khu vực 3 | N18: Far Region | O18: Near Region | P18: Same Region | Q18: Far Region | R18: Near Region | S18: Same Region
C19: Special Lane | D19: 3 | E19: 3 | F19: 4 | G19: 4 | H19: 12
L20: Model | M20: Type | N20: ID | O20: Mã đơn | P20: Kho lấy
L21: C2C | M21: Delivery | N21: 2590595 | O21: GTKMP + Mã đơn tiki | P21: Kho vùng
C22: Tuyến | D22: Thời gian giao hàng cam kết | G22: Thời gian cam kết trả hàng | H22: Thời gian Toàn Trình | L22: B2C DropShip | M22: Delivery | N22: 2590595 | O22: GTKMP + Mã đơn tiki | P22: Kho hàng lớn
D23: urban | E23: suburban 1 | F23: suburban 2 | L23: C2C C-Return | M23: C-Return | N23: 2590595 | O23: GTKMP + AMSPICK + Mã đơn tiki | P23: Kho vùng
C24: Intra Metro | D24: 1 | E24: 1 | F24: 1 | G24: 3 | H24: 10 | L24: B2C | M24: Delivery | N24: 1367 | O24: GHNTK + Mã đơn tiki | P24: Kho hàng lớn
C25: Same Province | D25: 1 | E25: 1 | F25: 2 | G25: 4 | H25: 11 | L25: B2C C-Return | M25: C-Return | N25: 1367 | O25: GHNTK + AMSPICK + Mã đơn tiki | P25: Kho vùng
C26: Same Region | D26: 2 | E26: 2 | F26: 3 | G26: 5 | H26: 14 | M26: System booking | N26: 2590595 & 1367 | O26: Số còn lại
C27: Near Region | D27: 3 | E27: 3 | F27: 4 | G27: 6 | H27: 14
C28: Far Region | D28: 4 | E28: 4 | F28: 5 | G28: 6 | H28: 14
C29: Special Lane | D29: 3 | E29: 3 | F29: 4 | G29: 6 | H29: 14

Sheet mapping 1
A1: Province/City | B1: District | D1: Urban | E1: Area
A2: An Giang | B2: Huyện An Phú | C2: =B2&" - "&A2 -> Huyện An Phú - An Giang | D2: suburban 2 | E2: South | F2: =COUNTIF($B:$B,B2) -> 1 | G2: =COUNTIF($C:$C,C2) -> 1
A3: An Giang | B3: Huyện Châu Phú | C3: =B3&" - "&A3 -> Huyện Châu Phú - An Giang | D3: suburban 2 | E3: South | F3: =COUNTIF($B:$B,B3) -> 1 | G3: =COUNTIF($C:$C,C3) -> 1
A4: An Giang | B4: Huyện Châu Thành | C4: =B4&" - "&A4 -> Huyện Châu Thành - An Giang | D4: suburban 1 | E4: South | F4: =COUNTIF($B:$B,B4) -> 10 | G4: =COUNTIF($C:$C,C4) -> 1
A5: An Giang | B5: Huyện Chợ Mới | C5: =B5&" - "&A5 -> Huyện Chợ Mới - An Giang | D5: suburban 2 | E5: South | F5: =COUNTIF($B:$B,B5) -> 2 | G5: =COUNTIF($C:$C,C5) -> 1
A6: An Giang | B6: Huyện Phú Tân | C6: =B6&" - "&A6 -> Huyện Phú Tân - An Giang | D6: suburban 2 | E6: South | F6: =COUNTIF($B:$B,B6) -> 2 | G6: =COUNTIF($C:$C,C6) -> 1
A7: An Giang | B7: Huyện Thoại Sơn | C7: =B7&" - "&A7 -> Huyện Thoại Sơn - An Giang | D7: suburban 2 | E7: South | F7: =COUNTIF($B:$B,B7) -> 1 | G7: =COUNTIF($C:$C,C7) -> 1
A8: An Giang | B8: Huyện Tịnh Biên | C8: =B8&" - "&A8 -> Huyện Tịnh Biên - An Giang | D8: suburban 2 | E8: South | F8: =COUNTIF($B:$B,B8) -> 1 | G8: =COUNTIF($C:$C,C8) -> 1
A9: An Giang | B9: Huyện Tri Tôn | C9: =B9&" - "&A9 -> Huyện Tri Tôn - An Giang | D9: suburban 2 | E9: South | F9: =COUNTIF($B:$B,B9) -> 1 | G9: =COUNTIF($C:$C,C9) -> 1
A10: An Giang | B10: Thành phố Châu Đốc | C10: =B10&" - "&A10 -> Thành phố Châu Đốc - An Giang | D10: suburban 2 | E10: South | F10: =COUNTIF($B:$B,B10) -> 1 | G10: =COUNTIF($C:$C,C10) -> 1
A11: An Giang | B11: Thành phố Long Xuyên | C11: =B11&" - "&A11 -> Thành phố Long Xuyên - An Giang | D11: urban | E11: South | F11: =COUNTIF($B:$B,B11) -> 1 | G11: =COUNTIF($C:$C,C11) -> 1
A12: An Giang | B12: Huyện Tân Châu | C12: =B12&" - "&A12 -> Huyện Tân Châu - An Giang | D12: suburban 2 | E12: South | F12: =COUNTIF($B:$B,B12) -> 2 | G12: =COUNTIF($C:$C,C12) -> 1
A13: Bà Rịa - Vũng Tàu | B13: Huyện Châu Đức | C13: =B13&" - "&A13 -> Huyện Châu Đức - Bà Rịa - Vũng Tàu | D13: suburban 1 | E13: South | F13: =COUNTIF($B:$B,B13) -> 1 | G13: =COUNTIF($C:$C,C13) -> 1
... A19: Bà Rịa - Vũng Tàu | B19: Thành phố Bà Rịa | C19: =B19&" - "&A19 -> Thành phố Bà Rịa - Bà Rịa - Vũng Tàu | D19: urban | E19: South | F19: =COUNTIF($B:$B,B19) -> 1 | G19: =COUNTIF($C:$C,C19) -> 1
A20: Bà Rịa - Vũng Tàu | B20: TT Phú Mỹ | C20: =B20&" - "&A20 -> TT Phú Mỹ - Bà Rịa - Vũng Tàu | D20: suburban 2 | E20: South
A21: Bà Rịa - Vũng Tàu | B21: Thị Xã Phú Mỹ | C21: =B21&" - "&A21 -> Thị Xã Phú Mỹ - Bà Rịa - Vũng Tàu | D21: suburban 1 | E21: South
A22: Bà Rịa - Vũng Tàu | B22: Thành phố Vũng Tàu | C22: =B22&" - "&A22 -> Thành phố Vũng Tàu - Bà Rịa - Vũng Tàu | D22: urban | E22: South | F22: =COUNTIF($B:$B,B22) -> 1 | G22: =COUNTIF($C:$C,C22) -> 1
A23: Bắc Giang | B23: Huyện Hiệp Hòa | C23: =B23&" - "&A23 -> Huyện Hiệp Hòa - Bắc Giang | D23: suburban 2 | E23: North | F23: =COUNTIF($B:$B,B23) -> 1 | G23: =COUNTIF($C:$C,C23) -> 1
A24: Bắc Giang | B24: Huyện Lạng Giang | C24: =B24&" - "&A24 -> Huyện Lạng Giang - Bắc Giang | D24: suburban 2 | E24: North | F24: =COUNTIF($B:$B,B24) -> 1 | G24: =COUNTIF($C:$C,C24) -> 1
A25: Bắc Giang | B25: Huyện Lục Nam | C25: =B25&" - "&A25 -> Huyện Lục Nam - Bắc Giang | D25: suburban 1 | E25: North | F25: =COUNTIF($B:$B,B25) -> 1 | G25: =COUNTIF($C:$C,C25) -> 1
A26: Bắc Giang | B26: Huyện Lục Ngạn | C26: =B26&" - "&A26 -> Huyện Lục Ngạn - Bắc Giang | D26: suburban 2 | E26: North | F26: =COUNTIF($B:$B,B26) -> 1 | G26: =COUNTIF($C:$C,C26) -> 1
A27: Bắc Giang | B27: Huyện Sơn Động | C27: =B27&" - "&A27 -> Huyện Sơn Động - Bắc Giang | D27: suburban 2 | E27: North | F27: =COUNTIF($B:$B,B27) -> 1 | G27: =COUNTIF($C:$C,C27) -> 1
A28: Bắc Giang | B28: Huyện Tân Yên | C28: =B28&" - "&A28 -> Huyện Tân Yên - Bắc Giang | D28: suburban 2 | E28: North | F28: =COUNTIF($B:$B,B28) -> 1 | G28: =COUNTIF($C:$C,C28) -> 1
A29: Bắc Giang | B29: Huyện Việt Yên | C29: =B29&" - "&A29 -> Huyện Việt Yên - Bắc Giang | D29: suburban 1 | E29: North | F29: =COUNTIF($B:$B,B29) -> 1 | G29: =COUNTIF($C:$C,C29) -> 1
A30: Bắc Giang | B30: Huyện Yên Dũng | C30: =B30&" - "&A30 -> Huyện Yên Dũng - Bắc Giang | D30: suburban 1 | E30: North | F30: =COUNTIF($B:$B,B30) -> 1 | G30: =COUNTIF($C:$C,C30) -> 1
A31: Bắc Giang | B31: Huyện Yên Thế | C31: =B31&" - "&A31 -> Huyện Yên Thế - Bắc Giang | D31: suburban 2 | E31: North | F31: =COUNTIF($B:$B,B31) -> 1 | G31: =COUNTIF($C:$C,C31) -> 1
A32: Bắc Giang | B32: Thành phố Bắc Giang | C32: =B32&" - "&A32 -> Thành phố Bắc Giang - Bắc Giang | D32: urban | E32: North | F32: =COUNTIF($B:$B,B32) -> 1 | G32: =COUNTIF($C:$C,C32) -> 1
A33: Bắc Kạn | B33: Huyện Ba Bể | C33: =B33&" - "&A33 -> Huyện Ba Bể - Bắc Kạn | D33: suburban 2 | E33: North | F33: =COUNTIF($B:$B,B33) -> 1 | G33: =COUNTIF($C:$C,C33) -> 1
... A200: Đồng Tháp | B200: Thành phố Sa Đéc | C200: =B200&" - "&A200 -> Thành phố Sa Đéc - Đồng Tháp | D200: suburban 1 | E200: South | F200: =COUNTIF($B:$B,B200) -> 1 | G200: =COUNTIF($C:$C,C200) -> 1
A201: Đồng Tháp | B201: Đồng Tháp | C201: =B201&" - "&A201 -> Đồng Tháp - Đồng Tháp | D201: urban | E201: South
A202: Đồng Tháp | B202: Thị xã Hồng Ngự | C202: =B202&" - "&A202 -> Thị xã Hồng Ngự - Đồng Tháp | D202: suburban 2 | E202: South | F202: =COUNTIF($B:$B,B202) -> 1 | G202: =COUNTIF($C:$C,C202) -> 1
A203: Gia Lai | B203: Huyện Chư Păh | C203: =B203&" - "&A203 -> Huyện Chư Păh - Gia Lai | D203: suburban 1 | E203: South | F203: =COUNTIF($B:$B,B203) -> 1 | G203: =COUNTIF($C:$C,C203) -> 1
A204: Gia Lai | B204: Huyện Chư Prông | C204: =B204&" - "&A204 -> Huyện Chư Prông - Gia Lai | D204: suburban 2 | E204: South | F204: =COUNTIF($B:$B,B204) -> 1 | G204: =COUNTIF($C:$C,C204) -> 1
A205: Gia Lai | B205: Huyện Chư Pưh | C205: =B205&" - "&A205 -> Huyện Chư Pưh - Gia Lai | D205: suburban 2 | E205: South | F205: =COUNTIF($B:$B,B205) -> 1 | G205: =COUNTIF($C:$C,C205) -> 1
A206: Gia Lai | B206: Huyện Chư Sê | C206: =B206&" - "&A206 -> Huyện Chư Sê - Gia Lai | D206: suburban 2 | E206: South | F206: =COUNTIF($B:$B,B206) -> 1 | G206: =COUNTIF($C:$C,C206) -> 1
A207: Gia Lai | B207: Huyện Đắk Đoa | C207: =B207&" - "&A207 -> Huyện Đắk Đoa - Gia Lai | D207: suburban 1 | E207: South | F207: =COUNTIF($B:$B,B207) -> 1 | G207: =COUNTIF($C:$C,C207) -> 1
A208: Gia Lai | B208: Huyện Đắk Pơ | C208: =B208&" - "&A208 -> Huyện Đắk Pơ - Gia Lai | D208: suburban 2 | E208: South | F208: =COUNTIF($B:$B,B208) -> 1 | G208: =COUNTIF($C:$C,C208) -> 1
A209: Gia Lai | B209: Huyện Đức Cơ | C209: =B209&" - "&A209 -> Huyện Đức Cơ - Gia Lai | D209: suburban 2 | E209: South | F209: =COUNTIF($B:$B,B209) -> 1 | G209: =COUNTIF($C:$C,C209) -> 1
A210: Gia Lai | B210: Huyện Ia Grai | C210: =B210&" - "&A210 -> Huyện Ia Grai - Gia Lai | D210: suburban 1 | E210: South | F210: =COUNTIF($B:$B,B210) -> 1 | G210: =COUNTIF($C:$C,C210) -> 1
A211: Gia Lai | B211: Huyện Ia Pa | C211: =B211&" - "&A211 -> Huyện Ia Pa - Gia Lai | D211: suburban 2 | E211: South | F211: =COUNTIF($B:$B,B211) -> 1 | G211: =COUNTIF($C:$C,C211) -> 1
...

Sheet Sheet1
A1: STT | B1: Ngày tạo | C1: Mã PH | D1: Thời gian | E1: Mã Shop | F1: Tên người nhận | G1: ĐC Giao Hàng | H1: TG Kết Thúc G/H | I1: TG Kết Thúc L/H | J1: TG KT Trả Hàng | K1: Tiền thu | L1: Ngày chuyển COD | M1: Tình Trạng | N1: Kho lấy | O1: Từ Quận | P1: Đến Quận | Q1: DS Dịch vụ | R1: Khối lượng | S1: Khối lượng quy đổi | T1: KL tính cước | U1: KL tăng kg | V1: Cước thường | W1: Trả hàng | X1: Phí vận chuyển | Y1: Tổng cước | Z1: Khu vực lấy | AA1: Khu vực giao | AB1: Cước hệ thống | AC1: Tiki note | AD1: KL thay đổi | AE1: Kho bàn giao | AF1: Kho đến | AG1: MATCH | AH1: KL tính cước | AI1: Mức cước | AJ1: Cước giao | AK1: Cước trả | AL1: Cước Luân chuyển | AM1: Tổng cước | AN1: So sánh | AO1: Tiki note | AP1: GHN note
A2: 29052 | B2: 43939.617 | C2: 31421781764802 | D2: Tuần 4 | E2: RMA10406429-355498150 | F2: TIKI | G2: Kho 3C Unidepot, số 9 đường Nguyễn Văn Tạo, Long Thới, Nhà Bè, TPHCM | H2: 43943.702 | I2: 43939.82 | K2: 0 | M2: Giao thành công/Chờ hoàn tất | N2: 1898 - Bưu Cục 162 Huỳnh Thúc Kháng | O2: Huyện Nam Giang - Quảng Nam | P2: Quận Đặc Biệt DC - Hồ Chí Minh | Q2: 3 Ngày | R2: 200 | S2: 200 | T2: =MAX(R2,S2) -> 200 | U2: =INT(IF(T2<=3000,0,IF(MOD(((T2-1000)/1000)/0.5,1)>0,INT(T2-3000)/1000*2+1,INT(T2-3000)/1000*2))) -> 0 | V2: =VLOOKUP(O2,#REF!,VLOOKUP(T2/1000,#REF!,2,TRUE),FALSE)+MAX(0,ROUNDUP(T2/1000*2,0)/2-3)*2*VLOOKUP(O2,#REF!,10,FALSE) -> #REF! | W2: =IF(LEFT(M2,3)="Trả",VLOOKUP(P2,#REF!,11,0),0) -> 0 | X2: =IF(AND(N2="1327 - Kho Khách hàng lớn Hồ Chí Minh 01",OR(AA2="Khu vực 3", AA2="Hà Nội")),MAX(0,ROUNDUP(T2/1000,0))*VLOOKUP(P2,#REF!,12,0),0) -> 0 | Y2: =SUM(V2:X2) -> #REF! | Z2: Khu vực 2 | AA2: Hồ Chí Minh | AB2: 39600
A3: 29053 | B3: 43945.696 | C3: 31421781549376 | D3: Tuần 4 | E3: RMA10580956-512262188 | F3: TIKI | G3: Kho 3C Unidepot, số 9 đường Nguyễn Văn Tạo, Long Thới, Nhà Bè, TPHCM | H3: 43949.742 | I3: 43946.695 | K3: 0 | M3: Giao thành công/Chờ hoàn tất | N3: 1152 - Bưu Cục Lê Anh Xuân | O3: Huyện Phú Ninh - Quảng Nam | P3: Quận Đặc Biệt DC - Hồ Chí Minh | Q3: 3 Ngày | R3: 500 | S3: 200 | T3: =MAX(R3,S3) -> 500 | U3: =INT(IF(T3<=3000,0,IF(MOD(((T3-1000)/1000)/0.5,1)>0,INT(T3-3000)/1000*2+1,INT(T3-3000)/1000*2))) -> 0 | V3: =VLOOKUP(O3,#REF!,VLOOKUP(T3/1000,#REF!,2,TRUE),FALSE)+MAX(0,ROUNDUP(T3/1000*2,0)/2-3)*2*VLOOKUP(O3,#REF!,10,FALSE) -> #REF! | W3: =IF(LEFT(M3,3)="Trả",VLOOKUP(P3,#REF!,11,0),0) -> 0 | X3: =IF(AND(N3="1327 - Kho Khách hàng lớn Hồ Chí Minh 01",OR(AA3="Khu vực 3", AA3="Hà Nội")),MAX(0,ROUNDUP(T3/1000,0))*VLOOKUP(P3,#REF!,12,0),0) -> 0 | Y3: =SUM(V3:X3) -> #REF! | Z3: Khu vực 2 | AA3: Hồ Chí Minh | AB3: 39600
